Workbook
Name Slicer_DepartmentType: #N/A
Name Slicer_Quarters__ExitDate: #N/A
Name Slicer_TerminationType: #N/A
Name Slicer_Training_Type: #N/A
Name Slicer_Years__ExitDate: #N/A

Sheet 1. Retention & Workforce Moveme
A3: Sum of Turnover | B3: Column Labels
A4: Row Labels | B4: 2018 | C4: 2019 | D4: 2020 | E4: 2021 | F4: 2022 | G4: 2023 | H4: Grand Total
A5: Qtr1 | C5: 1263 | D5: 7921 | E5: 20155 | F5: 44699 | G5: 111398 | H5: 185436
A6: Qtr2 | C6: 1468 | D6: 9856 | E6: 30018 | F6: 54765 | G6: 132439 | H6: 228546
A7: Qtr3 | C7: 2455 | D7: 16572 | E7: 42456 | F7: 79924 | G7: 68014 | H7: 209421
A8: Qtr4 | B8: 229 | C8: 6879 | D8: 18456 | E8: 48451 | F8: 88213 | H8: 162228
A9: Grand Total | B9: 229 | C9: 12065 | D9: 52805 | E9: 141080 | F9: 267601 | G9: 311851 | H9: 785631
A18: Department type | B18: Count of Employee ID
A19: Admin Offices | B19: 51
A20: Executive Office | B20: 20
A21: IT/IS | B21: 241
A22: Production | B22: 1054
A23: Sales | B23: 171
A24: Software Engineering | B24: 69
A25: Grand Total | B25: 1606
A33: Count of GenderCode | B33: Column Labels
A34: Row Labels | B34: Female | C34: Male | D34: Grand Total
A35: Admin Offices | B35: 30 | C35: 21 | D35: 51
A36: Executive Office | B36: 1 | C36: 19 | D36: 20
A37: IT/IS | B37: 115 | C37: 126 | D37: 241
A38: Production | B38: 673 | C38: 381 | D38: 1054
A39: Sales | B39: 58 | C39: 113 | D39: 171
A40: Software Engineering | B40: 31 | C40: 38 | D40: 69
A41: Grand Total | B41: 908 | C41: 698 | D41: 1606
A49: State | B49: Count of Employee ID | D49: State | E49: Count of Employee ID
A50: MA | B50: 1427 | D50: =A50 -> MA | E50: =GETPIVOTDATA("Employee ID",$A$49,"State","MA") -> 1427
A51: TX | B51: 32 | D51: =A51 -> TX | E51: =GETPIVOTDATA("Employee ID",$A$49,"State","TX") -> 32
A52: CT | B52: 20 | D52: =A52 -> CT | E52: =GETPIVOTDATA("Employee ID",$A$49,"State","CT") -> 20
A53: ID | B53: 16 | D53: =A53 -> ID | E53: =GETPIVOTDATA("Employee ID",$A$49,"State","ID") -> 16
A54: TN | B54: 14 | D54: =A54 -> TN | E54: =GETPIVOTDATA("Employee ID",$A$49,"State","TN") -> 14
A55: AZ | B55: 14 | D55: =A55 -> AZ | E55: =GETPIVOTDATA("Employee ID",$A$49,"State","AZ") -> 14
A56: KY | B56: 13 | D56: =A56 -> KY | E56: =GETPIVOTDATA("Employee ID",$A$49,"State","KY") -> 13
A57: CO | B57: 11 | D57: =A57 -> CO | E57: =GETPIVOTDATA("Employee ID",$A$49,"State","CO") -> 11
A58: WA | B58: 10 | D58: =A58 -> WA | E58: =GETPIVOTDATA("Employee ID",$A$49,"State","WA") -> 10
A59: IN | B59: 9 | D59: =A59 -> IN | E59: =GETPIVOTDATA("Employee ID",$A$49,"State","IN") -> 9
A60: CA | B60: 6 | D60: =A60 -> CA | E60: =GETPIVOTDATA("Employee ID",$A$49,"State","CA") -> 6
A61: PA | B61: 5 | D61: =A61 -> PA | E61: =GETPIVOTDATA("Employee ID",$A$49,"State","PA") -> 5
A62: NY | B62: 4 | D62: =A62 -> NY | E62: =GETPIVOTDATA("Employee ID",$A$49,"State","NY") -> 4
A63: OR | B63: 4 | D63: =A63 -> OR | E63: =GETPIVOTDATA("Employee ID",$A$49,"State","OR") -> 4
A64: ND | B64: 4 | D64: =A64 -> ND | E64: =GETPIVOTDATA("Employee ID",$A$49,"State","ND") -> 4
...

Sheet Employee Turnover & Retention
A1: EmployeeStatus | B1: (Multiple Items)
A3: Row Labels | B3: Count of Employee ID
A4: Involuntary | B4: 153
A5: Resignation | B5: 133
A6: Retirement | B6: 138
A7: Voluntary | B7: 143
A8: Grand Total | B8: 567
A19: Department | B19: Average of Tenure (years)
A20: Executive Office | B20: 1.9450474
A21: Production | B21: 1.3464895
A22: IT/IS | B22: 1.2574558
A23: Sales | B23: 1.1075975
A24: Admin Offices | B24: 1.0839934
A25: Software Engineering | B25: 0.87081907
A26: Grand Total | B26: 1.2972024
A33: EmployeeStatus | B33: (Multiple Items)
A35: Turnover time | B35: Count of Employee ID
A36: 2018 | B36: 1
A37: 2019 | B37: 15
A38: 2020 | B38: 40
A39: 2021 | B39: 68
A40: 2022 | B40: 123
A41: 2023 | B41: 161
A42: Grand Total | B42: 408

Sheet Performance & Employee Engageme
A3: Performance | B3: Average of Satisfaction Score | C3: Average of Engagement Score
A4: Exceeds | B4: 2.7720207 | C4: 2.8134715
A5: Fully Meets | B5: 3.0694006 | C5: 2.9684543
A6: Needs Improvement | B6: 3.0106383 | C6: 2.9361702
A7: PIP | B7: 2.7843137 | C7: 2.7254902
A8: Grand Total | B8: 3.0211706 | C8: 2.9402242
A14: Pay Zone | B14: Average of Satisfaction Score
A15: Zone A | B15: 2.9677419
A16: Zone B | B16: 3.0833333
A17: Zone C | B17: 3.0137795
A18: Grand Total | B18: 3.0211706

Sheet Training & Development Analytic
A3: Tarining Program Name | B3: Sum of Training Cost | C3: Average of Training Duration(Days)
A4: Communication Skills | B4: 192132.22 | C4: 2.9719101
A5: Customer Service | B5: 172887.82 | C5: 2.9013158
A6: Leadership Development | B6: 175129.14 | C6: 3.0662252
A7: Project Management | B7: 174816.37 | C7: 3.0677419
A8: Technical Skills | B8: 184973.25 | C8: 2.8323353
A9: Grand Total | B9: 899938.8 | C9: 2.9657534
A17: Count of Training Outcome | B17: Column Labels
A18: Tarining Program Name | B18: Completed | C18: Failed | D18: Incomplete | E18: Passed | F18: Grand Total
A19: External | B19: 174 | C19: 216 | D19: 213 | E19: 194 | F19: 797
A20: Internal | B20: 214 | C20: 191 | D20: 215 | E20: 189 | F20: 809
A21: Grand Total | B21: 388 | C21: 407 | D21: 428 | E21: 383 | F21: 1606
A30: Buisness Unit | B30: Sum of Training Cost
A31: BPC | B31: 85818.91
A32: EW | B32: 85850.06
A33: PYZ | B33: 86822.93
A34: PL | B34: 87307.03
A35: MSC | B35: 88005.91
A36: CCDR | B36: 88760.66
A37: NEL | B37: 89292
A38: TNS | B38: 92413.29
A39: WBL | B39: 92788.7
A40: SVG | B40: 102879.31
A41: Grand Total | B41: 899938.8

Sheet KPIs
B9: Column Labels
B10: Completed | C10: Failed | D10: Incomplete | E10: Passed | F10: Grand Total
A11: Sum of Employee ID | B11: 993084 | C11: 1031933 | D11: 1079186 | E11: 932290 | F11: 4036493
B12: =GETPIVOTDATA("Employee ID",$A$9,"Training Outcome","Completed")/GETPIVOTDATA("Employee ID",$A$9) -> 0.24602644 | C12: =GETPIVOTDATA("Employee ID",$A$9,"Training Outcome","Failed")/GETPIVOTDATA("Employee ID",$A$9) -> 0.25565088 | D12: =GETPIVOTDATA("Employee ID",$A$9,"Training Outcome","Incomplete")/GETPIVOTDATA("Employee ID",$A$9) -> 0.26735733 | E12: =GETPIVOTDATA("Employee ID",$A$9,"Training Outcome","Passed")/GETPIVOTDATA("Employee ID",$A$9) -> 0.23096535 | F12: =SUM(B12:E12) -> 1
A16: Row Labels | B16: Average of Engagement Score | C16: Average of Satisfaction Score
A17: Female | B17: 2.9262115 | C17: 3.0187225
A18: Male | B18: 2.9584527 | C18: 3.0243553
A19: Grand Total | B19: 2.9402242 | C19: 3.0211706
A23: Row Labels | B23: Count of Employee ID
A24: Involuntary | B24: 407
A25: Resignation | B25: 397
A26: Retirement | B26: 393
A27: Voluntary | B27: 409
A28: Grand Total | B28: 1606
A31: Average of Tenure (years)
A32: 1.3393153
A35: Row Labels | B35: Sum of Employee ID
A36: Exceeds | B36: 0.11894508
A37: Fully Meets | B37: 0.784589
A38: Needs Improvement | B38: 0.058394255
A39: PIP | B39: 0.038071663
A40: Grand Total | B40: 1

Sheet HR_Dashboard (pg 4)

Sheet HR_Dashboard (pg 3)

Sheet HR_Dashboard (pg 2)

Sheet HR_Dashboard
G7: ''''''''''''''''''''''''''''''''''''''''''''''''
J12: =GETPIVOTDATA("Tenure (years)",KPIs!$A$31) -> 1.3393153 | M12: =GETPIVOTDATA("Employee ID",KPIs!$A$9,"Training Outcome","Completed") -> 993084 | P12: =GETPIVOTDATA("Employee ID",KPIs!$A$23) -> 1606 | T12: =GETPIVOTDATA("Average of Satisfaction Score",KPIs!$A$16) -> 3.0211706
G16: ][[][]][][][][[d
G24: ""

Sheet Cleaned_HR_Dataset_Detailed
A1: ID | B1: FirstName | C1: LastName | D1: StartDate | E1: ExitDate | F1: Turnover | G1: Tenure (years) | H1: Title | I1: Supervisor | J1: ADEmail | K1: BusinessUnit | L1: EmployeeStatus | M1: EmployeeType | N1: PayZone | O1: EmployeeClassificationType | P1: TerminationType | Q1: DepartmentType | R1: Division | S1: DOB | T1: State | U1: JobFunctionDescription | V1: GenderCode | W1: LocationCode | X1: Performance Score | Y1: Current Employee Rating | Z1: Employee ID | AA1: Survey Date | AB1: Engagement Score | AC1: Satisfaction Score | AD1: Training Date | AE1: Training Program Name | AF1: Training Type | AG1: Training Outcome | AH1: Location | AI1: Trainer | AJ1: Training Duration(Days) | AK1: Training Cost
A2: 6 | B2: Latia | C2: Costa | D2: 44657 | E2: 45110 | F2: =Table2[[#This Row],[ExitDate]]-Table2[[#This Row],[StartDate]] -> 453 | G2: =(Table2[[#This Row],[ExitDate]]-Table2[[#This Row],[StartDate]])/365.25 -> 1.2402464 | H2: Area Sales Manager | I2: Jacob Braun | J2: latia.costa@bilearner.com | K2: WBL | L2: Active | M2: Full-Time | N2: Zone B | O2: Temporary | P2: Involuntary | Q2: Sales | R2: General - Eng | S2: 15348 | T2: CA | U2: Technician | V2: Female | W2: 90007 | X2: Exceeds | Y2: 4 | Z2: 3433 | AA2: 25-03-2023 | AB2: 1 | AC2: 5 | AD2: 44779 | AE2: Customer Service | AF2: External | AG2: Passed | AH2: Lancehaven | AI2: David Stewart | AJ2: 5 | AK2: 295.08
A3: 7 | B3: Sharlene | C3: Terry | D3: 44141 | E3: 44955 | F3: =Table2[[#This Row],[ExitDate]]-Table2[[#This Row],[StartDate]] -> 814 | G3: =(Table2[[#This Row],[ExitDate]]-Table2[[#This Row],[StartDate]])/365.25 -> 2.2286105 | H3: Area Sales Manager | I3: Tracy Marquez | J3: sharlene.terry@bilearner.com | K3: CCDR | L3: Active | M3: Contract | N3: Zone C | O3: Full-Time | P3: Involuntary | Q3: Sales | R3: Engineers | S3: 21004 | T3: OR | U3: Engineer | V3: Female | W3: 97756 | X3: Fully Meets | Y3: 2 | Z3: 3434 | AA3: 21-04-2023 | AB3: 1 | AC3: 4 | AD3: 44841 | AE3: Leadership Development | AF3: Internal | AG3: Passed | AH3: Jeremyshire | AI3: Stephanie Garza | AJ3: 3 | AK3: 790.15
A4: 9 | B4: Joseph | C4: Martins | D4: 44582 | E4: 45106 | F4: =Table2[[#This Row],[ExitDate]]-Table2[[#This Row],[StartDate]] -> 524 | G4: =(Table2[[#This Row],[ExitDate]]-Table2[[#This Row],[StartDate]])/365.25 -> 1.4346338 | H4: Area Sales Manager | I4: George Jenkins | J4: joseph.martins@bilearner.com | K4: BPC | L4: Active | M4: Part-Time | N4: Zone B | O4: Temporary | P4: Resignation | Q4: Sales | R4: Engineers | S4: 18213 | T4: TX | U4: Engineer | V4: Male | W4: 78207 | X4: Fully Meets | Y4: 5 | Z4: 3436 | AA4: 30-07-2023 | AB4: 5 | AC4: 5 | AD4: 45025 | AE4: Leadership Development | AF4: Internal | AG4: Failed | AH4: Nicolebury | AI4: Megan Wilson | AJ4: 5 | AK4: 192.61
A5: 11 | B5: Dheepa | C5: Nguyen | D5: 43322 | E5: 43773 | F5: =Table2[[#This Row],[ExitDate]]-Table2[[#This Row],[StartDate]] -> 451 | G5: =(Table2[[#This Row],[ExitDate]]-Table2[[#This Row],[StartDate]])/365.25 -> 1.2347707 | H5: Area Sales Manager | I5: Brian Miller | J5: dheepa.nguyen@bilearner.com | K5: MSC | L5: Active | M5: Full-Time | N5: Zone C | O5: Temporary | P5: Retirement | Q5: Sales | R5: General - Con | S5: 17688 | T5: GA | U5: Technician | V5: Female | W5: 30428 | X5: Fully Meets | Y5: 3 | Z5: 3438 | AA5: 28-10-2022 | AB5: 4 | AC5: 2 | AD5: 44839 | AE5: Technical Skills | AF5: Internal | AG5: Failed | AH5: Nunezmouth | AI5: Sharon Flores DDS | AJ5: 2 | AK5: 208.17
A6: 12 | B6: Bartholemew | C6: Khemmich | D6: 44706 | E6: 44892 | F6: =Table2[[#This Row],[ExitDate]]-Table2[[#This Row],[StartDate]] -> 186 | G6: =(Table2[[#This Row],[ExitDate]]-Table2[[#This Row],[StartDate]])/365.25 -> 0.50924025 | H6: Area Sales Manager | I6: Charles Parks | J6: bartholemew.khemmich@bilearner.com | K6: EW | L6: Active | M6: Full-Time | N6: Zone A | O6: Temporary | P6: Involuntary | Q6: Sales | R6: Splicing | S6: 24-11-1981 | T6: CO | U6: Splicer | V6: Male | W6: 80820 | X6: Fully Meets | Y6: 3 | Z6: 3439 | AA6: 30-10-2022 | AB6: 1 | AC6: 2 | AD6: 44994 | AE6: Technical Skills | AF6: External | AG6: Incomplete | AH6: Port Margaretview | AI6: Kimberly Garcia | AJ6: 1 | AK6: 421.07
A7: 13 | B7: Xana | C7: Potts | D7: 43804 | E7: 44974 | F7: =Table2[[#This Row],[ExitDate]]-Table2[[#This Row],[StartDate]] -> 1170 | G7: =(Table2[[#This Row],[ExitDate]]-Table2[[#This Row],[StartDate]])/365.25 -> 3.2032854 | H7: Area Sales Manager | I7: Gregory Walker | J7: xana.potts@bilearner.com | K7: CCDR | L7: Active | M7: Contract | N7: Zone A | O7: Full-Time | P7: Resignation | Q7: Sales | R7: Finance & Accounting | S7: 18790 | T7: KY | U7: Controller | V7: Female | W7: 40220 | X7: Fully Meets | Y7: 3 | Z7: 3440 | AA7: 24-09-2022 | AB7: 1 | AC7: 4 | AD7: 45075 | AE7: Communication Skills | AF7: External | AG7: Failed | AH7: Nancyview | AI7: Christopher Underwood | AJ7: 1 | AK7: 649.03
A8: 15 | B8: Kaylah | C8: Moon | D8: 43655 | E8: 44728 | F8: =Table2[[#This Row],[ExitDate]]-Table2[[#This Row],[StartDate]] -> 1073 | G8: =(Table2[[#This Row],[ExitDate]]-Table2[[#This Row],[StartDate]])/365.25 -> 2.9377139 | H8: Area Sales Manager | I8: Ashley Scott | J8: kaylah.moon@bilearner.com | K8: PYZ | L8: Active | M8: Full-Time | N8: Zone A | O8: Full-Time | P8: Retirement | Q8: IT/IS | R8: Field Operations | S8: 24-11-1952 | T8: MA | U8: Laborer | V8: Male | W8: 2810 | X8: Exceeds | Y8: 2 | Z8: 3442 | AA8: 31-10-2022 | AB8: 2 | AC8: 5 | AD8: 44991 | AE8: Project Management | AF8: External | AG8: Failed | AH8: Port Davidshire | AI8: Victoria Berry | AJ8: 4 | AK8: 286.87
A9: 16 | B9: Kristen | C9: Tate | D9: 44291 | E9: 45058 | F9: =Table2[[#This Row],[ExitDate]]-Table2[[#This Row],[StartDate]] -> 767 | G9: =(Table2[[#This Row],[ExitDate]]-Table2[[#This Row],[StartDate]])/365.25 -> 2.0999316 | H9: Area Sales Manager | I9: Lauren Jones | J9: kristen.tate@bilearner.com | K9: WBL | L9: Active | M9: Full-Time | N9: Zone C | O9: Part-Time | P9: Voluntary | Q9: IT/IS | R9: Project Management - Con | S9: 34550 | T9: KY | U9: Coordinator | V9: Male | W9: 2621 | X9: Fully Meets | Y9: 3 | Z9: 3443 | AA9: 29-04-2023 | AB9: 2 | AC9: 2 | AD9: 44975 | AE9: Technical Skills | AF9: External | AG9: Failed | AH9: East Katie | AI9: Gary Thornton | AJ9: 3 | AK9: 402.13
A10: 17 | B10: Bobby | C10: Rodgers | D10: 44528 | E10: 44596 | F10: =Table2[[#This Row],[ExitDate]]-Table2[[#This Row],[StartDate]] -> 68 | G10: =(Table2[[#This Row],[ExitDate]]-Table2[[#This Row],[StartDate]])/365.25 -> 0.18617385 | H10: Area Sales Manager | I10: Matthew Jackson | J10: bobby.rodgers@bilearner.com | K10: NEL | L10: Active | M10: Contract | N10: Zone A | O10: Part-Time | P10: Voluntary | Q10: Sales | R10: Engineers | S10: 15-11-1983 | T10: KY | U10: Director | V10: Male | W10: 44553 | X10: Fully Meets | Y10: 3 | Z10: 3444 | AA10: 14-12-2022 | AB10: 1 | AC10: 2 | AD10: 44867 | AE10: Technical Skills | AF10: External | AG10: Failed | AH10: Jacobburgh | AI10: William Willis | AJ10: 2 | AK10: 388.84
A11: 20 | B11: Mariela | C11: Schultz | D11: 43977 | E11: 45095 | F11: =Table2[[#This Row],[ExitDate]]-Table2[[#This Row],[StartDate]] -> 1118 | G11: =(Table2[[#This Row],[ExitDate]]-Table2[[#This Row],[StartDate]])/365.25 -> 3.0609172 | H11: Area Sales Manager | I11: Michelle Evans MD | J11: mariela.schultz@bilearner.com | K11: CCDR | L11: Future Start | M11: Part-Time | N11: Zone C | O11: Part-Time | P11: Involuntary | Q11: Sales | R11: General - Con | S11: 17-02-1964 | T11: TX | U11: Technician | V11: Female | W11: 43481 | X11: Fully Meets | Y11: 3 | Z11: 3447 | AA11: 45143 | AB11: 5 | AC11: 1 | AD11: 45018 | AE11: Customer Service | AF11: Internal | AG11: Incomplete | AH11: Kristenton | AI11: Kimberly Doyle | AJ11: 3 | AK11: 353.21
A12: 21 | B12: Angela | C12: Molina | D12: 43739 | E12: 44141 | F12: =Table2[[#This Row],[ExitDate]]-Table2[[#This Row],[StartDate]] -> 402 | G12: =(Table2[[#This Row],[ExitDate]]-Table2[[#This Row],[StartDate]])/365.25 -> 1.100616 | H12: Area Sales Manager | I12: Patricia Cook | J12: angela.molina@bilearner.com | K12: SVG | L12: Future Start | M12: Full-Time | N12: Zone A | O12: Temporary | P12: Retirement | Q12: Sales | R12: Engineers | S12: 21524 | T12: TX | U12: Specialist | V12: Male | W12: 50705 | X12: Fully Meets | Y12: 3 | Z12: 3448 | AA12: 28-03-2023 | AB12: 5 | AC12: 1 | AD12: 45062 | AE12: Communication Skills | AF12: Internal | AG12: Completed | AH12: West Jamesview | AI12: Lindsay Williams | AJ12: 4 | AK12: 911.05
A13: 22 | B13: Gerald | C13: Preston | D13: 45056 | E13: 45073 | F13: =Table2[[#This Row],[ExitDate]]-Table2[[#This Row],[StartDate]] -> 17 | G13: =(Table2[[#This Row],[ExitDate]]-Table2[[#This Row],[StartDate]])/365.25 -> 0.046543463 | H13: Area Sales Manager | I13: Ashley Reeves | J13: gerald.preston@bilearner.com | K13: EW | L13: Future Start | M13: Contract | N13: Zone B | O13: Temporary | P13: Involuntary | Q13: Sales | R13: General - Eng | S13: 18-09-1992 | T13: CO | U13: Technician | V13: Male | W13: 5168 | X13: Fully Meets | Y13: 5 | Z13: 3449 | AA13: 30-06-2023 | AB13: 3 | AC13: 2 | AD13: 44836 | AE13: Communication Skills | AF13: External | AG13: Completed | AH13: Josebury | AI13: Joseph Faulkner | AJ13: 3 | AK13: 242.21
A14: 23 | B14: Reilly | C14: Moyer | D14: 44075 | E14: 44899 | F14: =Table2[[#This Row],[ExitDate]]-Table2[[#This Row],[StartDate]] -> 824 | G14: =(Table2[[#This Row],[ExitDate]]-Table2[[#This Row],[StartDate]])/365.25 -> 2.255989 | H14: Area Sales Manager | I14: Stanley Harvey | J14: reilly.moyer@bilearner.com | K14: MSC | L14: Active | M14: Contract | N14: Zone C | O14: Temporary | P14: Resignation | Q14: Sales | R14: Field Operations | S14: 34646 | T14: CO | U14: Operator | V14: Male | W14: 11765 | X14: Exceeds | Y14: 2 | Z14: 3450 | AA14: 18-01-2023 | AB14: 4 | AC14: 3 | AD14: 44938 | AE14: Technical Skills | AF14: Internal | AG14: Completed | AH14: South Benjaminfurt | AI14: Laura Davis | AJ14: 4 | AK14: 186.07
A15: 24 | B15: Carlee | C15: French | D15: 44245 | E15: 44876 | F15: =Table2[[#This Row],[ExitDate]]-Table2[[#This Row],[StartDate]] -> 631 | G15: =(Table2[[#This Row],[ExitDate]]-Table2[[#This Row],[StartDate]])/365.25 -> 1.7275838 | H15: Area Sales Manager | I15: Michael Bradshaw | J15: carlee.french@bilearner.com | K15: TNS | L15: Active | M15: Contract | N15: Zone C | O15: Full-Time | P15: Voluntary | Q15: Sales | R15: General - Con | S15: 15-01-1968 | T15: CO | U15: Technician | V15: Male | W15: 71071 | X15: Exceeds | Y15: 3 | Z15: 3451 | AA15: 29-04-2023 | AB15: 5 | AC15: 1 | AD15: 45007 | AE15: Technical Skills | AF15: External | AG15: Completed | AH15: Duncanview | AI15: d | AJ15: 1 | AK15: 921.97
A16: 28 | B16: Charity | C16: Miranda | D16: 44376 | E16: 44747 | F16: =Table2[[#This Row],[ExitDate]]-Table2[[#This Row],[StartDate]] -> 371 | G16: =(Table2[[#This Row],[ExitDate]]-Table2[[#This Row],[StartDate]])/365.25 -> 1.0157426 | H16: Area Sales Manager | I16: Daniel Rodriguez | J16: charity.miranda@bilearner.com | K16: WBL | L16: Active | M16: Full-Time | N16: Zone C | O16: Temporary | P16: Resignation | Q16: Sales | R16: Project Management - Eng | S16: 18-01-1999 | T16: KY | U16: Manager | V16: Male | W16: 3763 | X16: Exceeds | Y16: 4 | Z16: 3455 | AA16: 44903 | AB16: 2 | AC16: 1 | AD16: 45002 | AE16: Project Management | AF16: External | AG16: Passed | AH16: Wadefurt | AI16: Timothy Moreno | AJ16: 1 | AK16: 220.41
A17: 31 | B17: Cory | C17: Robinson | D17: 44679 | E17: 45070 | F17: =Table2[[#This Row],[ExitDate]]-Table2[[#This Row],[StartDate]] -> 391 | G17: =(Table2[[#This Row],[ExitDate]]-Table2[[#This Row],[StartDate]])/365.25 -> 1.0704997 | H17: Area Sales Manager | I17: Elizabeth Anderson | J17: cory.robinson@bilearner.com | K17: BPC | L17: Future Start | M17: Contract | N17: Zone A | O17: Full-Time | P17: Voluntary | Q17: Sales | R17: Field Operations | S17: 35407 | T17: TX | U17: Laborer | V17: Female | W17: 5194 | X17: Needs Improvement | Y17: 3 | Z17: 3458 | AA17: 14-02-2023 | AB17: 2 | AC17: 5 | AD17: 44897 | AE17: Communication Skills | AF17: Internal | AG17: Failed | AH17: North Deborahville | AI17: Joseph Ward | AJ17: 2 | AK17: 409.27
A18: 32 | B18: Saniya | C18: Yu | D18: 44304 | E18: 44733 | F18: =Table2[[#This Row],[ExitDate]]-Table2[[#This Row],[StartDate]] -> 429 | G18: =(Table2[[#This Row],[ExitDate]]-Table2[[#This Row],[StartDate]])/365.25 -> 1.174538 | H18: Area Sales Manager | I18: Erin Bailey | J18: saniya.yu@bilearner.com | K18: CCDR | L18: Future Start | M18: Part-Time | N18: Zone A | O18: Full-Time | P18: Retirement | Q18: Sales | R18: General - Con | S18: 16317 | T18: TX | U18: Splicer | V18: Male | W18: 8779 | X18: Exceeds | Y18: 2 | Z18: 3459 | AA18: 26-10-2022 | AB18: 4 | AC18: 4 | AD18: 45091 | AE18: Communication Skills | AF18: Internal | AG18: Passed | AH18: Chapmanbury | AI18: Joseph Thomas | AJ18: 4 | AK18: 168.32
A19: 34 | B19: Lincoln | C19: Compton | D19: 43664 | E19: 44470 | F19: =Table2[[#This Row],[ExitDate]]-Table2[[#This Row],[StartDate]] -> 806 | G19: =(Table2[[#This Row],[ExitDate]]-Table2[[#This Row],[StartDate]])/365.25 -> 2.2067077 | H19: Area Sales Manager | I19: Tammy Conner | J19: lincoln.compton@bilearner.com | K19: EW | L19: Future Start | M19: Full-Time | N19: Zone C | O19: Part-Time | P19: Resignation | Q19: Sales | R19: General - Con | S19: 29-12-1997 | T19: CO | U19: Foreman | V19: Male | W19: 78046 | X19: Needs Improvement | Y19: 1 | Z19: 3461 | AA19: 24-04-2023 | AB19: 1 | AC19: 4 | AD19: 44931 | AE19: Technical Skills | AF19: External | AG19: Completed | AH19: Taylorland | AI19: Micheal Munoz | AJ19: 2 | AK19: 948.43
A20: 35 | B20: Aliana | C20: Nolan | D20: 43356 | E20: 44456 | F20: =Table2[[#This Row],[ExitDate]]-Table2[[#This Row],[StartDate]] -> 1100 | G20: =(Table2[[#This Row],[ExitDate]]-Table2[[#This Row],[StartDate]])/365.25 -> 3.0116359 | H20: Area Sales Manager | I20: Brianna Mathews | J20: aliana.nolan@bilearner.com | K20: MSC | L20: Active | M20: Contract | N20: Zone A | O20: Full-Time | P20: Involuntary | Q20: Sales | R20: Field Operations | S20: 15592 | T20: CO | U20: Coordinator | V20: Male | W20: 27270 | X20: Needs Improvement | Y20: 3 | Z20: 3462 | AA20: 44784 | AB20: 3 | AC20: 3 | AD20: 45126 | AE20: Project Management | AF20: External | AG20: Completed | AH20: Erinville | AI20: Stacey Esparza | AJ20: 1 | AK20: 320.01
A21: 36 | B21: Kayden | C21: Dodson | D21: 43951 | E21: 44395 | F21: =Table2[[#This Row],[ExitDate]]-Table2[[#This Row],[StartDate]] -> 444 | G21: =(Table2[[#This Row],[ExitDate]]-Table2[[#This Row],[StartDate]])/365.25 -> 1.2156057 | H21: Area Sales Manager | I21: Jessica Peters | J21: kayden.dodson@bilearner.com | K21: TNS | L21: Active | M21: Part-Time | N21: Zone A | O21: Temporary | P21: Retirement | Q21: Sales | R21: Field Operations | S21: 21-06-1951 | T21: IN | U21: Tower Hand | V21: Male | W21: 12703 | X21: Fully Meets | Y21: 1 | Z21: 3463 | AA21: 18-09-2022 | AB21: 4 | AC21: 3 | AD21: 44802 | AE21: Technical Skills | AF21: Internal | AG21: Incomplete | AH21: Harperchester | AI21: Heather Edwards | AJ21: 4 | AK21: 926.19
A22: 37 | B22: James | C22: Duke | D22: 43437 | E22: 44813 | F22: =Table2[[#This Row],[ExitDate]]-Table2[[#This Row],[StartDate]] -> 1376 | G22: =(Table2[[#This Row],[ExitDate]]-Table2[[#This Row],[StartDate]])/365.25 -> 3.7672827 | H22: Area Sales Manager | I22: Mark Harris | J22: james.duke@bilearner.com | K22: PYZ | L22: Active | M22: Contract | N22: Zone B | O22: Full-Time | P22: Involuntary | Q22: Sales | R22: Shop (Fleet) | S22: 17-06-1998 | T22: MA | U22: Mechanic | V22: Male | W22: 66835 | X22: Needs Improvement | Y22: 5 | Z22: 3464 | AA22: 29-12-2022 | AB22: 2 | AC22: 5 | AD22: 44878 | AE22: Customer Service | AF22: External | AG22: Passed | AH22: Trevorside | AI22: Michaela Wright | AJ22: 2 | AK22: 290.47
A23: 39 | B23: Clayton | C23: Walker | D23: 44664 | E23: 45026 | F23: =Table2[[#This Row],[ExitDate]]-Table2[[#This Row],[StartDate]] -> 362 | G23: =(Table2[[#This Row],[ExitDate]]-Table2[[#This Row],[StartDate]])/365.25 -> 0.99110198 | H23: Area Sales Manager | I23: Jon Holden | J23: clayton.walker@bilearner.com | K23: PYZ | L23: Active | M23: Part-Time | N23: Zone C | O23: Full-Time | P23: Retirement | Q23: IT/IS | R23: Aerial | S23: 26-01-1979 | T23: KY | U23: Supervisor | V23: Male | W23: 64288 | X23: Exceeds | Y23: 4 | Z23: 3466 | AA23: 45024 | AB23: 1 | AC23: 3 | AD23: 44902 | AE23: Customer Service | AF23: External | AG23: Passed | AH23: West Angelaside | AI23: Erika Jackson | AJ23: 3 | AK23: 447.66
A24: 42 | B24: Ryland | C24: Shepherd | D24: 44041 | E24: 44931 | F24: =Table2[[#This Row],[ExitDate]]-Table2[[#This Row],[StartDate]] -> 890 | G24: =(Table2[[#This Row],[ExitDate]]-Table2[[#This Row],[StartDate]])/365.25 -> 2.4366872 | H24: Area Sales Manager | I24: James Berry | J24: ryland.shepherd@bilearner.com | K24: PL | L24: Future Start | M24: Contract | N24: Zone B | O24: Full-Time | P24: Resignation | Q24: Sales | R24: Field Operations | S24: 21-02-1945 | T24: TX | U24: Driver | V24: Female | W24: 81905 | X24: Needs Improvement | Y24: 3 | Z24: 3469 | AA24: 44934 | AB24: 5 | AC24: 5 | AD24: 44788 | AE24: Communication Skills | AF24: Internal | AG24: Failed | AH24: North Jeanetteville | AI24: Lisa Barnes | AJ24: 2 | AK24: 552.54
A25: 43 | B25: Esteban | C25: Gilbert | D25: 43418 | E25: 43766 | F25: =Table2[[#This Row],[ExitDate]]-Table2[[#This Row],[StartDate]] -> 348 | G25: =(Table2[[#This Row],[ExitDate]]-Table2[[#This Row],[StartDate]])/365.25 -> 0.95277207 | H25: Area Sales Manager | I25: Gail Ali | J25: esteban.gilbert@bilearner.com | K25: BPC | L25: Future Start | M25: Contract | N25: Zone C | O25: Part-Time | P25: Retirement | Q25: Sales | R25: Field Operations | S25: 31-05-1997 | T25: TX | U25: Technician | V25: Female | W25: 12491 | X25: Needs Improvement | Y25: 3 | Z25: 3470 | AA25: 45082 | AB25: 1 | AC25: 2 | AD25: 44830 | AE25: Project Management | AF25: External | AG25: Passed | AH25: New Molly | AI25: Katie Wong MD | AJ25: 1 | AK25: 986.96
A26: 48 | B26: Vance | C26: Trujillo | D26: 44460 | E26: 45029 | F26: =Table2[[#This Row],[ExitDate]]-Table2[[#This Row],[StartDate]] -> 569 | G26: =(Table2[[#This Row],[ExitDate]]-Table2[[#This Row],[StartDate]])/365.25 -> 1.5578371 | H26: Area Sales Manager | I26: Rebecca Simpson | J26: vance.trujillo@bilearner.com | K26: TNS | L26: Active | M26: Full-Time | N26: Zone C | O26: Temporary | P26: Resignation | Q26: Sales | R26: General - Con | S26: 25-12-1957 | T26: IN | U26: Foreman | V26: Male | W26: 90406 | X26: Fully Meets | Y26: 2 | Z26: 3475 | AA26: 25-01-2023 | AB26: 4 | AC26: 3 | AD26: 44867 | AE26: Customer Service | AF26: Internal | AG26: Passed | AH26: South Taylorfurt | AI26: Jenna Sherman | AJ26: 2 | AK26: 648.76
A27: 49 | B27: Charlie | C27: Koch | D27: 45089 | E27: 45113 | F27: =Table2[[#This Row],[ExitDate]]-Table2[[#This Row],[StartDate]] -> 24 | G27: =(Table2[[#This Row],[ExitDate]]-Table2[[#This Row],[StartDate]])/365.25 -> 0.065708419 | H27: Area Sales Manager | I27: Samantha Cardenas | J27: charlie.koch@bilearner.com | K27: PYZ | L27: Active | M27: Part-Time | N27: Zone A | O27: Temporary | P27: Voluntary | Q27: Sales | R27: Fielders | S27: 20-06-1945 | T27: MA | U27: Engineer | V27: Male | W27: 95774 | X27: Needs Improvement | Y27: 2 | Z27: 3476 | AA27: 44988 | AB27: 5 | AC27: 5 | AD27: 44883 | AE27: Leadership Development | AF27: Internal | AG27: Incomplete | AH27: Stephanieshire | AI27: Dr. Margaret Allen | AJ27: 4 | AK27: 533.5
A28: 51 | B28: Thomas | C28: Chandler | D28: 43360 | E28: 43474 | F28: =Table2[[#This Row],[ExitDate]]-Table2[[#This Row],[StartDate]] -> 114 | G28: =(Table2[[#This Row],[ExitDate]]-Table2[[#This Row],[StartDate]])/365.25 -> 0.31211499 | H28: Area Sales Manager | I28: Richard Hodges | J28: thomas.chandler@bilearner.com | K28: WBL | L28: Active | M28: Full-Time | N28: Zone C | O28: Temporary | P28: Resignation | Q28: Sales | R28: Wireline Construction | S28: 21103 | T28: KY | U28: Groundman | V28: Female | W28: 45149 | X28: Fully Meets | Y28: 2 | Z28: 3478 | AA28: 29-11-2022 | AB28: 3 | AC28: 4 | AD28: 44839 | AE28: Technical Skills | AF28: External | AG28: Incomplete | AH28: Port Matthew | AI28: Daniel Solomon | AJ28: 1 | AK28: 526.74
A29: 52 | B29: Sarai | C29: Stone | D29: 44775 | E29: 45018 | F29: =Table2[[#This Row],[ExitDate]]-Table2[[#This Row],[StartDate]] -> 243 | G29: =(Table2[[#This Row],[ExitDate]]-Table2[[#This Row],[StartDate]])/365.25 -> 0.66529774 | H29: Area Sales Manager | I29: Madison Wilson | J29: sarai.stone@bilearner.com | K29: NEL | L29: Active | M29: Contract | N29: Zone A | O29: Part-Time | P29: Involuntary | Q29: Sales | R29: Project Management - Con | S29: 17-05-1962 | T29: TX | U29: Technician | V29: Female | W29: 96336 | X29: Fully Meets | Y29: 2 | Z29: 3479 | AA29: 44631 | AB29: 4 | AC29: 4 | AD29: 44944 | AE29: Communication Skills | AF29: Internal | AG29: Passed | AH29: Stephanieburgh | AI29: Michael Dixon | AJ29: 3 | AK29: 443.45
A30: 53 | B30: Jerimiah | C30: Harmon | D30: 44812 | E30: 44850 | F30: =Table2[[#This Row],[ExitDate]]-Table2[[#This Row],[StartDate]] -> 38 | G30: =(Table2[[#This Row],[ExitDate]]-Table2[[#This Row],[StartDate]])/365.25 -> 0.10403833 | H30: Area Sales Manager | I30: Eric King | J30: jerimiah.harmon@bilearner.com | K30: PL | L30: Future Start | M30: Full-Time | N30: Zone C | O30: Temporary | P30: Retirement | Q30: Sales | R30: Catv | S30: 17053 | T30: TX | U30: Supervisor | V30: Female | W30: 75671 | X30: Fully Meets | Y30: 1 | Z30: 3480 | AA30: 25-07-2023 | AB30: 1 | AC30: 5 | AD30: 44987 | AE30: Leadership Development | AF30: External | AG30: Failed | AH30: North Amyfurt | AI30: Robert Hill | AJ30: 1 | AK30: 887.15
A31: 54 | B31: Leland | C31: Allen | D31: 43531 | E31: 44347 | F31: =Table2[[#This Row],[ExitDate]]-Table2[[#This Row],[StartDate]] -> 816 | G31: =(Table2[[#This Row],[ExitDate]]-Table2[[#This Row],[StartDate]])/365.25 -> 2.2340862 | H31: Area Sales Manager | I31: Brandon Harris | J31: leland.allen@bilearner.com | K31: BPC | L31: Future Start | M31: Full-Time | N31: Zone C | O31: Part-Time | P31: Voluntary | Q31: Sales | R31: Wireline Construction | S31: 24058 | T31: TX | U31: Splicer | V31: Male | W31: 61149 | X31: Fully Meets | Y31: 4 | Z31: 3481 | AA31: 44960 | AB31: 5 | AC31: 2 | AD31: 45075 | AE31: Technical Skills | AF31: External | AG31: Incomplete | AH31: East Charleston | AI31: Glenda Ryan | AJ31: 5 | AK31: 758.95
A32: 55 | B32: Cristal | C32: Bolton | D32: 43767 | E32: 44234 | F32: =Table2[[#This Row],[ExitDate]]-Table2[[#This Row],[StartDate]] -> 467 | G32: =(Table2[[#This Row],[ExitDate]]-Table2[[#This Row],[StartDate]])/365.25 -> 1.2785763 | H32: Area Sales Manager | I32: Matthew Flores | J32: cristal.bolton@bilearner.com | K32: CCDR | L32: Future Start | M32: Full-Time | N32: Zone A | O32: Temporary | P32: Resignation | Q32: Sales | R32: Catv | S32: 33179 | T32: TX | U32: Lineman | V32: Male | W32: 57302 | X32: Needs Improvement | Y32: 2 | Z32: 3482 | AA32: 22-10-2022 | AB32: 4 | AC32: 5 | AD32: 44988 | AE32: Technical Skills | AF32: Internal | AG32: Failed | AH32: Saraland | AI32: Jennifer Brown | AJ32: 1 | AK32: 627.11
A33: 59 | B33: Brendon | C33: Mcconnell | D33: 44865 | E33: 45085 | F33: =Table2[[#This Row],[ExitDate]]-Table2[[#This Row],[StartDate]] -> 220 | G33: =(Table2[[#This Row],[ExitDate]]-Table2[[#This Row],[StartDate]])/365.25 -> 0.60232717 | H33: Area Sales Manager | I33: Victoria Krause | J33: brendon.mcconnell@bilearner.com | K33: TNS | L33: Active | M33: Part-Time | N33: Zone C | O33: Temporary | P33: Involuntary | Q33: Sales | R33: Fielders | S33: 14-11-1990 | T33: IN | U33: Engineer | V33: Male | W33: 19665 | X33: Fully Meets | Y33: 4 | Z33: 3486 | AA33: 27-08-2022 | AB33: 3 | AC33: 1 | AD33: 45130 | AE33: Project Management | AF33: Internal | AG33: Completed | AH33: Lake Angelafort | AI33: Daniel Jones | AJ33: 5 | AK33: 812.59
A34: 68 | B34: Tia | C34: Ellis | D34: 45099 | E34: 45129 | F34: =Table2[[#This Row],[ExitDate]]-Table2[[#This Row],[StartDate]] -> 30 | G34: =(Table2[[#This Row],[ExitDate]]-Table2[[#This Row],[StartDate]])/365.25 -> 0.082135524 | H34: Area Sales Manager | I34: Daniel Cabrera | J34: tia.ellis@bilearner.com | K34: TNS | L34: Active | M34: Part-Time | N34: Zone B | O34: Temporary | P34: Retirement | Q34: Sales | R34: Wireline Construction | S34: 27-01-1993 | T34: IN | U34: Laborer | V34: Male | W34: 1115 | X34: Fully Meets | Y34: 4 | Z34: 3495 | AA34: 44782 | AB34: 4 | AC34: 3 | AD34: 44916 | AE34: Customer Service | AF34: External | AG34: Passed | AH34: Port Andrew | AI34: Christian Higgins | AJ34: 1 | AK34: 701.55
A35: 71 | B35: Joel | C35: Mcmillan | D35: 45042 | E35: 45099 | F35: =Table2[[#This Row],[ExitDate]]-Table2[[#This Row],[StartDate]] -> 57 | G35: =(Table2[[#This Row],[ExitDate]]-Table2[[#This Row],[StartDate]])/365.25 -> 0.15605749 | H35: Area Sales Manager | I35: Peter Harvey | J35: joel.mcmillan@bilearner.com | K35: PYZ | L35: Active | M35: Full-Time | N35: Zone A | O35: Full-Time | P35: Voluntary | Q35: Sales | R35: General - Sga | S35: 17-10-1998 | T35: KY | U35: Laborer | V35: Female | W35: 36087 | X35: Fully Meets | Y35: 2 | Z35: 3498 | AA35: 19-06-2023 | AB35: 3 | AC35: 3 | AD35: 45076 | AE35: Project Management | AF35: External | AG35: Failed | AH35: Yorkport | AI35: Amy Clark | AJ35: 1 | AK35: 208.43
A36: 72 | B36: Maci | C36: Frost | D36: 43368 | E36: 44550 | F36: =Table2[[#This Row],[ExitDate]]-Table2[[#This Row],[StartDate]] -> 1182 | G36: =(Table2[[#This Row],[ExitDate]]-Table2[[#This Row],[StartDate]])/365.25 -> 3.2361396 | H36: Area Sales Manager | I36: Patrick Daniel | J36: maci.frost@bilearner.com | K36: WBL | L36: Active | M36: Part-Time | N36: Zone C | O36: Temporary | P36: Involuntary | Q36: Sales | R36: Field Operations | S36: 16-01-1971 | T36: KY | U36: Technician | V36: Female | W36: 61457 | X36: Fully Meets | Y36: 5 | Z36: 3499 | AA36: 21-07-2023 | AB36: 5 | AC36: 3 | AD36: 44956 | AE36: Technical Skills | AF36: Internal | AG36: Incomplete | AH36: East Bradley | AI36: Angela Lee | AJ36: 2 | AK36: 762.45
A37: 73 | B37: Nevaeh | C37: Lucas | D37: 43424 | E37: 44003 | F37: =Table2[[#This Row],[ExitDate]]-Table2[[#This Row],[StartDate]] -> 579 | G37: =(Table2[[#This Row],[ExitDate]]-Table2[[#This Row],[StartDate]])/365.25 -> 1.5852156 | H37: Area Sales Manager | I37: Bryan Douglas | J37: nevaeh.lucas@bilearner.com | K37: NEL | L37: Active | M37: Full-Time | N37: Zone B | O37: Part-Time | P37: Voluntary | Q37: Sales | R37: Shop (Fleet) | S37: 25-02-2000 | T37: TX | U37: Mechanic | V37: Female | W37: 80424 | X37: Fully Meets | Y37: 1 | Z37: 3500 | AA37: 14-05-2023 | AB37: 4 | AC37: 1 | AD37: 45092 | AE37: Leadership Development | AF37: External | AG37: Incomplete | AH37: Smithchester | AI37: Larry Morales | AJ37: 4 | AK37: 779.79
A38: 74 | B38: Garrett | C38: Zimmerman | D38: 44073 | E38: 44803 | F38: =Table2[[#This Row],[ExitDate]]-Table2[[#This Row],[StartDate]] -> 730 | G38: =(Table2[[#This Row],[ExitDate]]-Table2[[#This Row],[StartDate]])/365.25 -> 1.9986311 | H38: Area Sales Manager | I38: Destiny Hopkins | J38: garrett.zimmerman@bilearner.com | K38: PL | L38: Future Start | M38: Part-Time | N38: Zone A | O38: Part-Time | P38: Retirement | Q38: Sales | R38: General - Con | S38: 19-04-1959 | T38: TX | U38: Technician | V38: Male | W38: 6240 | X38: Fully Meets | Y38: 4 | Z38: 3501 | AA38: 20-02-2023 | AB38: 2 | AC38: 3 | AD38: 45086 | AE38: Project Management | AF38: External | AG38: Passed | AH38: South Kaylachester | AI38: Troy Adams | AJ38: 3 | AK38: 135.95
A39: 79 | B39: Laila | C39: Woodard | D39: 43704 | E39: 45056 | F39: =Table2[[#This Row],[ExitDate]]-Table2[[#This Row],[StartDate]] -> 1352 | G39: =(Table2[[#This Row],[ExitDate]]-Table2[[#This Row],[StartDate]])/365.25 -> 3.7015743 | H39: Area Sales Manager | I39: Jordan Vega | J39: laila.woodard@bilearner.com | K39: MSC | L39: Active | M39: Full-Time | N39: Zone B | O39: Temporary | P39: Voluntary | Q39: Sales | R39: Field Operations | S39: 32301 | T39: IN | U39: Technician | V39: Male | W39: 38740 | X39: Fully Meets | Y39: 2 | Z39: 3506 | AA39: 27-06-2023 | AB39: 2 | AC39: 2 | AD39: 45067 | AE39: Leadership Development | AF39: Internal | AG39: Completed | AH39: Deleonport | AI39: Jonathan Peterson | AJ39: 1 | AK39: 781.81
A40: 80 | B40: Ivan | C40: Huff | D40: 44252 | E40: 45023 | F40: =Table2[[#This Row],[ExitDate]]-Table2[[#This Row],[StartDate]] -> 771 | G40: =(Table2[[#This Row],[ExitDate]]-Table2[[#This Row],[StartDate]])/365.25 -> 2.110883 | H40: Area Sales Manager | I40: John Miller | J40: ivan.huff@bilearner.com | K40: TNS | L40: Active | M40: Full-Time | N40: Zone A | O40: Full-Time | P40: Retirement | Q40: Sales | R40: Project Management - Con | S40: 24-03-1973 | T40: CA | U40: Manager | V40: Male | W40: 9437 | X40: Fully Meets | Y40: 4 | Z40: 3507 | AA40: 31-03-2023 | AB40: 2 | AC40: 5 | AD40: 45071 | AE40: Project Management | AF40: Internal | AG40: Passed | AH40: Loriberg | AI40: Michael Copeland | AJ40: 4 | AK40: 651.77
...

Sheet Messy_HR_Dataset_Detailed
A1: ID | B1: FirstName | C1: LastName | D1: StartDate | E1: ExitDate | F1: Turnover | G1: Tenure (years) | H1: Title | I1: Supervisor | J1: ADEmail | K1: BusinessUnit | L1: EmployeeStatus | M1: EmployeeType | N1: PayZone | O1: EmployeeClassificationType | P1: TerminationType | Q1: DepartmentType | R1: Division | S1: DOB | T1: State | U1: JobFunctionDescription | V1: GenderCode | W1: LocationCode | X1: Performance Score | Y1: Current Employee Rating | Z1: Employee ID | AA1: Survey Date | AB1: Engagement Score | AC1: Satisfaction Score | AD1: Training Date | AE1: Training Program Name | AF1: Training Type | AG1: Training Outcome | AH1: Location | AI1: Trainer | AJ1: Training Duration(Days) | AK1: Training Cost
A2: 6 | B2: Latia | C2: Costa | D2: 44657 | E2: 45110 | F2: =Messy_HR_Dataset_Detailed!$E2-Messy_HR_Dataset_Detailed!$D2 -> 453 | G2: =(Messy_HR_Dataset_Detailed!$E2-Messy_HR_Dataset_Detailed!$D2)/365.25 -> 1.2402464 | H2: Area Sales Manager | I2: Jacob Braun | J2: latia.costa@bilearner.com | K2: WBL | L2: Active | M2: Full-Time | N2: Zone B | O2: Temporary | P2: Involuntary | Q2: Sales | R2: General - Eng | S2: 15348 | T2: CA | U2: Technician | V2: Female | W2: 90007 | X2: Exceeds | Y2: 4 | Z2: 3433 | AA2: 25-03-2023 | AB2: 1 | AC2: 5 | AD2: 44779 | AE2: Customer Service | AF2: External | AG2: Passed | AH2: Lancehaven | AI2: David Stewart | AJ2: 5 | AK2: 295.08
A3: 7 | B3: Sharlene | C3: Terry | D3: 44141 | E3: 44955 | F3: =Messy_HR_Dataset_Detailed!$E3-Messy_HR_Dataset_Detailed!$D3 -> 814 | G3: =(Messy_HR_Dataset_Detailed!$E3-Messy_HR_Dataset_Detailed!$D3)/365.25 -> 2.2286105 | H3: Area Sales Manager | I3: Tracy Marquez | J3: sharlene.terry@bilearner.com | K3: CCDR | L3: Active | M3: Contract | N3: Zone C | O3: Full-Time | P3: Involuntary | Q3: Sales | R3: Engineers | S3: 21004 | T3: OR | U3: Engineer | V3: Female | W3: 97756 | X3: Fully Meets | Y3: 2 | Z3: 3434 | AA3: 21-04-2023 | AB3: 1 | AC3: 4 | AD3: 44841 | AE3: Leadership Development | AF3: Internal | AG3: Passed | AH3: Jeremyshire | AI3: Stephanie Garza | AJ3: 3 | AK3: 790.15
A4: 9 | B4: Joseph | C4: Martins | D4: 44582 | E4: 45106 | F4: =Messy_HR_Dataset_Detailed!$E4-Messy_HR_Dataset_Detailed!$D4 -> 524 | G4: =(Messy_HR_Dataset_Detailed!$E4-Messy_HR_Dataset_Detailed!$D4)/365.25 -> 1.4346338 | H4: Area Sales Manager | I4: George Jenkins | J4: joseph.martins@bilearner.com | K4: BPC | L4: Active | M4: Part-Time | N4: Zone B | O4: Temporary | P4: Resignation | Q4: Sales | R4: Engineers | S4: 18213 | T4: TX | U4: Engineer | V4: Male | W4: 78207 | X4: Fully Meets | Y4: 5 | Z4: 3436 | AA4: 30-07-2023 | AB4: 5 | AC4: 5 | AD4: 45025 | AE4: Leadership Development | AF4: Internal | AG4: Failed | AH4: Nicolebury | AI4: Megan Wilson | AJ4: 5 | AK4: 192.61
A5: 11 | B5: Dheepa | C5: Nguyen | D5: 43322 | E5: 43773 | F5: =Messy_HR_Dataset_Detailed!$E5-Messy_HR_Dataset_Detailed!$D5 -> 451 | G5: =(Messy_HR_Dataset_Detailed!$E5-Messy_HR_Dataset_Detailed!$D5)/365.25 -> 1.2347707 | H5: Area Sales Manager | I5: Brian Miller | J5: dheepa.nguyen@bilearner.com | K5: MSC | L5: Active | M5: Full-Time | N5: Zone C | O5: Temporary | P5: Retirement | Q5: Sales | R5: General - Con | S5: 17688 | T5: GA | U5: Technician | V5: Female | W5: 30428 | X5: Fully Meets | Y5: 3 | Z5: 3438 | AA5: 28-10-2022 | AB5: 4 | AC5: 2 | AD5: 44839 | AE5: Technical Skills | AF5: Internal | AG5: Failed | AH5: Nunezmouth | AI5: Sharon Flores DDS | AJ5: 2 | AK5: 208.17
A6: 12 | B6: Bartholemew | C6: Khemmich | D6: 44706 | E6: 44892 | F6: =Messy_HR_Dataset_Detailed!$E6-Messy_HR_Dataset_Detailed!$D6 -> 186 | G6: =(Messy_HR_Dataset_Detailed!$E6-Messy_HR_Dataset_Detailed!$D6)/365.25 -> 0.50924025 | H6: Area Sales Manager | I6: Charles Parks | J6: bartholemew.khemmich@bilearner.com | K6: EW | L6: Active | M6: Full-Time | N6: Zone A | O6: Temporary | P6: Involuntary | Q6: Sales | R6: Splicing | S6: 24-11-1981 | T6: CO | U6: Splicer | V6: Male | W6: 80820 | X6: Fully Meets | Y6: 3 | Z6: 3439 | AA6: 30-10-2022 | AB6: 1 | AC6: 2 | AD6: 44994 | AE6: Technical Skills | AF6: External | AG6: Incomplete | AH6: Port Margaretview | AI6: Kimberly Garcia | AJ6: 1 | AK6: 421.07
A7: 13 | B7: Xana | C7: Potts | D7: 43804 | E7: 44974 | F7: =Messy_HR_Dataset_Detailed!$E7-Messy_HR_Dataset_Detailed!$D7 -> 1170 | G7: =(Messy_HR_Dataset_Detailed!$E7-Messy_HR_Dataset_Detailed!$D7)/365.25 -> 3.2032854 | H7: Area Sales Manager | I7: Gregory Walker | J7: xana.potts@bilearner.com | K7: CCDR | L7: Active | M7: Contract | N7: Zone A | O7: Full-Time | P7: Resignation | Q7: Sales | R7: Finance & Accounting | S7: 18790 | T7: KY | U7: Controller | V7: Female | W7: 40220 | X7: Fully Meets | Y7: 3 | Z7: 3440 | AA7: 24-09-2022 | AB7: 1 | AC7: 4 | AD7: 45075 | AE7: Communication Skills | AF7: External | AG7: Failed | AH7: Nancyview | AI7: Christopher Underwood | AJ7: 1 | AK7: 649.03
A8: 15 | B8: Kaylah | C8: Moon | D8: 43655 | E8: 44728 | F8: =Messy_HR_Dataset_Detailed!$E8-Messy_HR_Dataset_Detailed!$D8 -> 1073 | G8: =(Messy_HR_Dataset_Detailed!$E8-Messy_HR_Dataset_Detailed!$D8)/365.25 -> 2.9377139 | H8: Area Sales Manager | I8: Ashley Scott | J8: kaylah.moon@bilearner.com | K8: PYZ | L8: Active | M8: Full-Time | N8: Zone A | O8: Full-Time | P8: Retirement | Q8: IT/IS | R8: Field Operations | S8: 24-11-1952 | T8: MA | U8: Laborer | V8: Male | W8: 2810 | X8: Exceeds | Y8: 2 | Z8: 3442 | AA8: 31-10-2022 | AB8: 2 | AC8: 5 | AD8: 44991 | AE8: Project Management | AF8: External | AG8: Failed | AH8: Port Davidshire | AI8: Victoria Berry | AJ8: 4 | AK8: 286.87
A9: 16 | B9: Kristen | C9: Tate | D9: 44291 | E9: 45058 | F9: =Messy_HR_Dataset_Detailed!$E9-Messy_HR_Dataset_Detailed!$D9 -> 767 | G9: =(Messy_HR_Dataset_Detailed!$E9-Messy_HR_Dataset_Detailed!$D9)/365.25 -> 2.0999316 | H9: Area Sales Manager | I9: Lauren Jones | J9: kristen.tate@bilearner.com | K9: WBL | L9: Active | M9: Full-Time | N9: Zone C | O9: Part-Time | P9: Voluntary | Q9: IT/IS | R9: Project Management - Con | S9: 34550 | T9: KY | U9: Coordinator | V9: Male | W9: 2621 | X9: Fully Meets | Y9: 3 | Z9: 3443 | AA9: 29-04-2023 | AB9: 2 | AC9: 2 | AD9: 44975 | AE9: Technical Skills | AF9: External | AG9: Failed | AH9: East Katie | AI9: Gary Thornton | AJ9: 3 | AK9: 402.13
A10: 17 | B10: Bobby | C10: Rodgers | D10: 44528 | E10: 44596 | F10: =Messy_HR_Dataset_Detailed!$E10-Messy_HR_Dataset_Detailed!$D10 -> 68 | G10: =(Messy_HR_Dataset_Detailed!$E10-Messy_HR_Dataset_Detailed!$D10)/365.25 -> 0.18617385 | H10: Area Sales Manager | I10: Matthew Jackson | J10: bobby.rodgers@bilearner.com | K10: NEL | L10: Active | M10: Contract | N10: Zone A | O10: Part-Time | P10: Voluntary | Q10: Sales | R10: Engineers | S10: 15-11-1983 | T10: KY | U10: Director | V10: Male | W10: 44553 | X10: Fully Meets | Y10: 3 | Z10: 3444 | AA10: 14-12-2022 | AB10: 1 | AC10: 2 | AD10: 44867 | AE10: Technical Skills | AF10: External | AG10: Failed | AH10: Jacobburgh | AI10: William Willis | AJ10: 2 | AK10: 388.84
A11: 20 | B11: Mariela | C11: Schultz | D11: 43977 | E11: 45095 | F11: =Messy_HR_Dataset_Detailed!$E11-Messy_HR_Dataset_Detailed!$D11 -> 1118 | G11: =(Messy_HR_Dataset_Detailed!$E11-Messy_HR_Dataset_Detailed!$D11)/365.25 -> 3.0609172 | H11: Area Sales Manager | I11: Michelle Evans MD | J11: mariela.schultz@bilearner.com | K11: CCDR | L11: Future Start | M11: Part-Time | N11: Zone C | O11: Part-Time | P11: Involuntary | Q11: Sales | R11: General - Con | S11: 17-02-1964 | T11: TX | U11: Technician | V11: Female | W11: 43481 | X11: Fully Meets | Y11: 3 | Z11: 3447 | AA11: 45143 | AB11: 5 | AC11: 1 | AD11: 45018 | AE11: Customer Service | AF11: Internal | AG11: Incomplete | AH11: Kristenton | AI11: Kimberly Doyle | AJ11: 3 | AK11: 353.21
A12: 21 | B12: Angela | C12: Molina | D12: 43739 | E12: 44141 | F12: =Messy_HR_Dataset_Detailed!$E12-Messy_HR_Dataset_Detailed!$D12 -> 402 | G12: =(Messy_HR_Dataset_Detailed!$E12-Messy_HR_Dataset_Detailed!$D12)/365.25 -> 1.100616 | H12: Area Sales Manager | I12: Patricia Cook | J12: angela.molina@bilearner.com | K12: SVG | L12: Future Start | M12: Full-Time | N12: Zone A | O12: Temporary | P12: Retirement | Q12: Sales | R12: Engineers | S12: 21524 | T12: TX | U12: Specialist | V12: Male | W12: 50705 | X12: Fully Meets | Y12: 3 | Z12: 3448 | AA12: 28-03-2023 | AB12: 5 | AC12: 1 | AD12: 45062 | AE12: Communication Skills | AF12: Internal | AG12: Completed | AH12: West Jamesview | AI12: Lindsay Williams | AJ12: 4 | AK12: 911.05
A13: 22 | B13: Gerald | C13: Preston | D13: 45056 | E13: 45073 | F13: =Messy_HR_Dataset_Detailed!$E13-Messy_HR_Dataset_Detailed!$D13 -> 17 | G13: =(Messy_HR_Dataset_Detailed!$E13-Messy_HR_Dataset_Detailed!$D13)/365.25 -> 0.046543463 | H13: Area Sales Manager | I13: Ashley Reeves | J13: gerald.preston@bilearner.com | K13: EW | L13: Future Start | M13: Contract | N13: Zone B | O13: Temporary | P13: Involuntary | Q13: Sales | R13: General - Eng | S13: 18-09-1992 | T13: CO | U13: Technician | V13: Male | W13: 5168 | X13: Fully Meets | Y13: 5 | Z13: 3449 | AA13: 30-06-2023 | AB13: 3 | AC13: 2 | AD13: 44836 | AE13: Communication Skills | AF13: External | AG13: Completed | AH13: Josebury | AI13: Joseph Faulkner | AJ13: 3 | AK13: 242.21
A14: 23 | B14: Reilly | C14: Moyer | D14: 44075 | E14: 44899 | F14: =Messy_HR_Dataset_Detailed!$E14-Messy_HR_Dataset_Detailed!$D14 -> 824 | G14: =(Messy_HR_Dataset_Detailed!$E14-Messy_HR_Dataset_Detailed!$D14)/365.25 -> 2.255989 | H14: Area Sales Manager | I14: Stanley Harvey | J14: reilly.moyer@bilearner.com | K14: MSC | L14: Active | M14: Contract | N14: Zone C | O14: Temporary | P14: Resignation | Q14: Sales | R14: Field Operations | S14: 34646 | T14: CO | U14: Operator | V14: Male | W14: 11765 | X14: Exceeds | Y14: 2 | Z14: 3450 | AA14: 18-01-2023 | AB14: 4 | AC14: 3 | AD14: 44938 | AE14: Technical Skills | AF14: Internal | AG14: Completed | AH14: South Benjaminfurt | AI14: Laura Davis | AJ14: 4 | AK14: 186.07
A15: 24 | B15: Carlee | C15: French | D15: 44245 | E15: 44876 | F15: =Messy_HR_Dataset_Detailed!$E15-Messy_HR_Dataset_Detailed!$D15 -> 631 | G15: =(Messy_HR_Dataset_Detailed!$E15-Messy_HR_Dataset_Detailed!$D15)/365.25 -> 1.7275838 | H15: Area Sales Manager | I15: Michael Bradshaw | J15: carlee.french@bilearner.com | K15: TNS | L15: Active | M15: Contract | N15: Zone C | O15: Full-Time | P15: Voluntary | Q15: Sales | R15: General - Con | S15: 15-01-1968 | T15: CO | U15: Technician | V15: Male | W15: 71071 | X15: Exceeds | Y15: 3 | Z15: 3451 | AA15: 29-04-2023 | AB15: 5 | AC15: 1 | AD15: 45007 | AE15: Technical Skills | AF15: External | AG15: Completed | AH15: Duncanview | AI15: d | AJ15: 1 | AK15: 921.97
A16: 28 | B16: Charity | C16: Miranda | D16: 44376 | E16: 44747 | F16: =Messy_HR_Dataset_Detailed!$E16-Messy_HR_Dataset_Detailed!$D16 -> 371 | G16: =(Messy_HR_Dataset_Detailed!$E16-Messy_HR_Dataset_Detailed!$D16)/365.25 -> 1.0157426 | H16: Area Sales Manager | I16: Daniel Rodriguez | J16: charity.miranda@bilearner.com | K16: WBL | L16: Active | M16: Full-Time | N16: Zone C | O16: Temporary | P16: Resignation | Q16: Sales | R16: Project Management - Eng | S16: 18-01-1999 | T16: KY | U16: Manager | V16: Male | W16: 3763 | X16: Exceeds | Y16: 4 | Z16: 3455 | AA16: 44903 | AB16: 2 | AC16: 1 | AD16: 45002 | AE16: Project Management | AF16: External | AG16: Passed | AH16: Wadefurt | AI16: Timothy Moreno | AJ16: 1 | AK16: 220.41
A17: 31 | B17: Cory | C17: Robinson | D17: 44679 | E17: 45070 | F17: =Messy_HR_Dataset_Detailed!$E17-Messy_HR_Dataset_Detailed!$D17 -> 391 | G17: =(Messy_HR_Dataset_Detailed!$E17-Messy_HR_Dataset_Detailed!$D17)/365.25 -> 1.0704997 | H17: Area Sales Manager | I17: Elizabeth Anderson | J17: cory.robinson@bilearner.com | K17: BPC | L17: Future Start | M17: Contract | N17: Zone A | O17: Full-Time | P17: Voluntary | Q17: Sales | R17: Field Operations | S17: 35407 | T17: TX | U17: Laborer | V17: Female | W17: 5194 | X17: Needs Improvement | Y17: 3 | Z17: 3458 | AA17: 14-02-2023 | AB17: 2 | AC17: 5 | AD17: 44897 | AE17: Communication Skills | AF17: Internal | AG17: Failed | AH17: North Deborahville | AI17: Joseph Ward | AJ17: 2 | AK17: 409.27
A18: 32 | B18: Saniya | C18: Yu | D18: 44304 | E18: 44733 | F18: =Messy_HR_Dataset_Detailed!$E18-Messy_HR_Dataset_Detailed!$D18 -> 429 | G18: =(Messy_HR_Dataset_Detailed!$E18-Messy_HR_Dataset_Detailed!$D18)/365.25 -> 1.174538 | H18: Area Sales Manager | I18: Erin Bailey | J18: saniya.yu@bilearner.com | K18: CCDR | L18: Future Start | M18: Part-Time | N18: Zone A | O18: Full-Time | P18: Retirement | Q18: Sales | R18: General - Con | S18: 16317 | T18: TX | U18: Splicer | V18: Male | W18: 8779 | X18: Exceeds | Y18: 2 | Z18: 3459 | AA18: 26-10-2022 | AB18: 4 | AC18: 4 | AD18: 45091 | AE18: Communication Skills | AF18: Internal | AG18: Passed | AH18: Chapmanbury | AI18: Joseph Thomas | AJ18: 4 | AK18: 168.32
A19: 34 | B19: Lincoln | C19: Compton | D19: 43664 | E19: 44470 | F19: =Messy_HR_Dataset_Detailed!$E19-Messy_HR_Dataset_Detailed!$D19 -> 806 | G19: =(Messy_HR_Dataset_Detailed!$E19-Messy_HR_Dataset_Detailed!$D19)/365.25 -> 2.2067077 | H19: Area Sales Manager | I19: Tammy Conner | J19: lincoln.compton@bilearner.com | K19: EW | L19: Future Start | M19: Full-Time | N19: Zone C | O19: Part-Time | P19: Resignation | Q19: Sales | R19: General - Con | S19: 29-12-1997 | T19: CO | U19: Foreman | V19: Male | W19: 78046 | X19: Needs Improvement | Y19: 1 | Z19: 3461 | AA19: 24-04-2023 | AB19: 1 | AC19: 4 | AD19: 44931 | AE19: Technical Skills | AF19: External | AG19: Completed | AH19: Taylorland | AI19: Micheal Munoz | AJ19: 2 | AK19: 948.43
A20: 35 | B20: Aliana | C20: Nolan | D20: 43356 | E20: 44456 | F20: =Messy_HR_Dataset_Detailed!$E20-Messy_HR_Dataset_Detailed!$D20 -> 1100 | G20: =(Messy_HR_Dataset_Detailed!$E20-Messy_HR_Dataset_Detailed!$D20)/365.25 -> 3.0116359 | H20: Area Sales Manager | I20: Brianna Mathews | J20: aliana.nolan@bilearner.com | K20: MSC | L20: Active | M20: Contract | N20: Zone A | O20: Full-Time | P20: Involuntary | Q20: Sales | R20: Field Operations | S20: 15592 | T20: CO | U20: Coordinator | V20: Male | W20: 27270 | X20: Needs Improvement | Y20: 3 | Z20: 3462 | AA20: 44784 | AB20: 3 | AC20: 3 | AD20: 45126 | AE20: Project Management | AF20: External | AG20: Completed | AH20: Erinville | AI20: Stacey Esparza | AJ20: 1 | AK20: 320.01
A21: 36 | B21: Kayden | C21: Dodson | D21: 43951 | E21: 44395 | F21: =Messy_HR_Dataset_Detailed!$E21-Messy_HR_Dataset_Detailed!$D21 -> 444 | G21: =(Messy_HR_Dataset_Detailed!$E21-Messy_HR_Dataset_Detailed!$D21)/365.25 -> 1.2156057 | H21: Area Sales Manager | I21: Jessica Peters | J21: kayden.dodson@bilearner.com | K21: TNS | L21: Active | M21: Part-Time | N21: Zone A | O21: Temporary | P21: Retirement | Q21: Sales | R21: Field Operations | S21: 21-06-1951 | T21: IN | U21: Tower Hand | V21: Male | W21: 12703 | X21: Fully Meets | Y21: 1 | Z21: 3463 | AA21: 18-09-2022 | AB21: 4 | AC21: 3 | AD21: 44802 | AE21: Technical Skills | AF21: Internal | AG21: Incomplete | AH21: Harperchester | AI21: Heather Edwards | AJ21: 4 | AK21: 926.19
A22: 37 | B22: James | C22: Duke | D22: 43437 | E22: 44813 | F22: =Messy_HR_Dataset_Detailed!$E22-Messy_HR_Dataset_Detailed!$D22 -> 1376 | G22: =(Messy_HR_Dataset_Detailed!$E22-Messy_HR_Dataset_Detailed!$D22)/365.25 -> 3.7672827 | H22: Area Sales Manager | I22: Mark Harris | J22: james.duke@bilearner.com | K22: PYZ | L22: Active | M22: Contract | N22: Zone B | O22: Full-Time | P22: Involuntary | Q22: Sales | R22: Shop (Fleet) | S22: 17-06-1998 | T22: MA | U22: Mechanic | V22: Male | W22: 66835 | X22: Needs Improvement | Y22: 5 | Z22: 3464 | AA22: 29-12-2022 | AB22: 2 | AC22: 5 | AD22: 44878 | AE22: Customer Service | AF22: External | AG22: Passed | AH22: Trevorside | AI22: Michaela Wright | AJ22: 2 | AK22: 290.47
A23: 39 | B23: Clayton | C23: Walker | D23: 44664 | E23: 45026 | F23: =Messy_HR_Dataset_Detailed!$E23-Messy_HR_Dataset_Detailed!$D23 -> 362 | G23: =(Messy_HR_Dataset_Detailed!$E23-Messy_HR_Dataset_Detailed!$D23)/365.25 -> 0.99110198 | H23: Area Sales Manager | I23: Jon Holden | J23: clayton.walker@bilearner.com | K23: PYZ | L23: Active | M23: Part-Time | N23: Zone C | O23: Full-Time | P23: Retirement | Q23: IT/IS | R23: Aerial | S23: 26-01-1979 | T23: KY | U23: Supervisor | V23: Male | W23: 64288 | X23: Exceeds | Y23: 4 | Z23: 3466 | AA23: 45024 | AB23: 1 | AC23: 3 | AD23: 44902 | AE23: Customer Service | AF23: External | AG23: Passed | AH23: West Angelaside | AI23: Erika Jackson | AJ23: 3 | AK23: 447.66
A24: 42 | B24: Ryland | C24: Shepherd | D24: 44041 | E24: 44931 | F24: =Messy_HR_Dataset_Detailed!$E24-Messy_HR_Dataset_Detailed!$D24 -> 890 | G24: =(Messy_HR_Dataset_Detailed!$E24-Messy_HR_Dataset_Detailed!$D24)/365.25 -> 2.4366872 | H24: Area Sales Manager | I24: James Berry | J24: ryland.shepherd@bilearner.com | K24: PL | L24: Future Start | M24: Contract | N24: Zone B | O24: Full-Time | P24: Resignation | Q24: Sales | R24: Field Operations | S24: 21-02-1945 | T24: TX | U24: Driver | V24: Female | W24: 81905 | X24: Needs Improvement | Y24: 3 | Z24: 3469 | AA24: 44934 | AB24: 5 | AC24: 5 | AD24: 44788 | AE24: Communication Skills | AF24: Internal | AG24: Failed | AH24: North Jeanetteville | AI24: Lisa Barnes | AJ24: 2 | AK24: 552.54
A25: 43 | B25: Esteban | C25: Gilbert | D25: 43418 | E25: 43766 | F25: =Messy_HR_Dataset_Detailed!$E25-Messy_HR_Dataset_Detailed!$D25 -> 348 | G25: =(Messy_HR_Dataset_Detailed!$E25-Messy_HR_Dataset_Detailed!$D25)/365.25 -> 0.95277207 | H25: Area Sales Manager | I25: Gail Ali | J25: esteban.gilbert@bilearner.com | K25: BPC | L25: Future Start | M25: Contract | N25: Zone C | O25: Part-Time | P25: Retirement | Q25: Sales | R25: Field Operations | S25: 31-05-1997 | T25: TX | U25: Technician | V25: Female | W25: 12491 | X25: Needs Improvement | Y25: 3 | Z25: 3470 | AA25: 45082 | AB25: 1 | AC25: 2 | AD25: 44830 | AE25: Project Management | AF25: External | AG25: Passed | AH25: New Molly | AI25: Katie Wong MD | AJ25: 1 | AK25: 986.96
A26: 48 | B26: Vance | C26: Trujillo | D26: 44460 | E26: 45029 | F26: =Messy_HR_Dataset_Detailed!$E26-Messy_HR_Dataset_Detailed!$D26 -> 569 | G26: =(Messy_HR_Dataset_Detailed!$E26-Messy_HR_Dataset_Detailed!$D26)/365.25 -> 1.5578371 | H26: Area Sales Manager | I26: Rebecca Simpson | J26: vance.trujillo@bilearner.com | K26: TNS | L26: Active | M26: Full-Time | N26: Zone C | O26: Temporary | P26: Resignation | Q26: Sales | R26: General - Con | S26: 25-12-1957 | T26: IN | U26: Foreman | V26: Male | W26: 90406 | X26: Fully Meets | Y26: 2 | Z26: 3475 | AA26: 25-01-2023 | AB26: 4 | AC26: 3 | AD26: 44867 | AE26: Customer Service | AF26: Internal | AG26: Passed | AH26: South Taylorfurt | AI26: Jenna Sherman | AJ26: 2 | AK26: 648.76
A27: 49 | B27: Charlie | C27: Koch | D27: 45089 | E27: 45113 | F27: =Messy_HR_Dataset_Detailed!$E27-Messy_HR_Dataset_Detailed!$D27 -> 24 | G27: =(Messy_HR_Dataset_Detailed!$E27-Messy_HR_Dataset_Detailed!$D27)/365.25 -> 0.065708419 | H27: Area Sales Manager | I27: Samantha Cardenas | J27: charlie.koch@bilearner.com | K27: PYZ | L27: Active | M27: Part-Time | N27: Zone A | O27: Temporary | P27: Voluntary | Q27: Sales | R27: Fielders | S27: 20-06-1945 | T27: MA | U27: Engineer | V27: Male | W27: 95774 | X27: Needs Improvement | Y27: 2 | Z27: 3476 | AA27: 44988 | AB27: 5 | AC27: 5 | AD27: 44883 | AE27: Leadership Development | AF27: Internal | AG27: Incomplete | AH27: Stephanieshire | AI27: Dr. Margaret Allen | AJ27: 4 | AK27: 533.5
A28: 51 | B28: Thomas | C28: Chandler | D28: 43360 | E28: 43474 | F28: =Messy_HR_Dataset_Detailed!$E28-Messy_HR_Dataset_Detailed!$D28 -> 114 | G28: =(Messy_HR_Dataset_Detailed!$E28-Messy_HR_Dataset_Detailed!$D28)/365.25 -> 0.31211499 | H28: Area Sales Manager | I28: Richard Hodges | J28: thomas.chandler@bilearner.com | K28: WBL | L28: Active | M28: Full-Time | N28: Zone C | O28: Temporary | P28: Resignation | Q28: Sales | R28: Wireline Construction | S28: 21103 | T28: KY | U28: Groundman | V28: Female | W28: 45149 | X28: Fully Meets | Y28: 2 | Z28: 3478 | AA28: 29-11-2022 | AB28: 3 | AC28: 4 | AD28: 44839 | AE28: Technical Skills | AF28: External | AG28: Incomplete | AH28: Port Matthew | AI28: Daniel Solomon | AJ28: 1 | AK28: 526.74
A29: 52 | B29: Sarai | C29: Stone | D29: 44775 | E29: 45018 | F29: =Messy_HR_Dataset_Detailed!$E29-Messy_HR_Dataset_Detailed!$D29 -> 243 | G29: =(Messy_HR_Dataset_Detailed!$E29-Messy_HR_Dataset_Detailed!$D29)/365.25 -> 0.66529774 | H29: Area Sales Manager | I29: Madison Wilson | J29: sarai.stone@bilearner.com | K29: NEL | L29: Active | M29: Contract | N29: Zone A | O29: Part-Time | P29: Involuntary | Q29: Sales | R29: Project Management - Con | S29: 17-05-1962 | T29: TX | U29: Technician | V29: Female | W29: 96336 | X29: Fully Meets | Y29: 2 | Z29: 3479 | AA29: 44631 | AB29: 4 | AC29: 4 | AD29: 44944 | AE29: Communication Skills | AF29: Internal | AG29: Passed | AH29: Stephanieburgh | AI29: Michael Dixon | AJ29: 3 | AK29: 443.45
A30: 53 | B30: Jerimiah | C30: Harmon | D30: 44812 | E30: 44850 | F30: =Messy_HR_Dataset_Detailed!$E30-Messy_HR_Dataset_Detailed!$D30 -> 38 | G30: =(Messy_HR_Dataset_Detailed!$E30-Messy_HR_Dataset_Detailed!$D30)/365.25 -> 0.10403833 | H30: Area Sales Manager | I30: Eric King | J30: jerimiah.harmon@bilearner.com | K30: PL | L30: Future Start | M30: Full-Time | N30: Zone C | O30: Temporary | P30: Retirement | Q30: Sales | R30: Catv | S30: 17053 | T30: TX | U30: Supervisor | V30: Female | W30: 75671 | X30: Fully Meets | Y30: 1 | Z30: 3480 | AA30: 25-07-2023 | AB30: 1 | AC30: 5 | AD30: 44987 | AE30: Leadership Development | AF30: External | AG30: Failed | AH30: North Amyfurt | AI30: Robert Hill | AJ30: 1 | AK30: 887.15
A31: 54 | B31: Leland | C31: Allen | D31: 43531 | E31: 44347 | F31: =Messy_HR_Dataset_Detailed!$E31-Messy_HR_Dataset_Detailed!$D31 -> 816 | G31: =(Messy_HR_Dataset_Detailed!$E31-Messy_HR_Dataset_Detailed!$D31)/365.25 -> 2.2340862 | H31: Area Sales Manager | I31: Brandon Harris | J31: leland.allen@bilearner.com | K31: BPC | L31: Future Start | M31: Full-Time | N31: Zone C | O31: Part-Time | P31: Voluntary | Q31: Sales | R31: Wireline Construction | S31: 24058 | T31: TX | U31: Splicer | V31: Male | W31: 61149 | X31: Fully Meets | Y31: 4 | Z31: 3481 | AA31: 44960 | AB31: 5 | AC31: 2 | AD31: 45075 | AE31: Technical Skills | AF31: External | AG31: Incomplete | AH31: East Charleston | AI31: Glenda Ryan | AJ31: 5 | AK31: 758.95
A32: 55 | B32: Cristal | C32: Bolton | D32: 43767 | E32: 44234 | F32: =Messy_HR_Dataset_Detailed!$E32-Messy_HR_Dataset_Detailed!$D32 -> 467 | G32: =(Messy_HR_Dataset_Detailed!$E32-Messy_HR_Dataset_Detailed!$D32)/365.25 -> 1.2785763 | H32: Area Sales Manager | I32: Matthew Flores | J32: cristal.bolton@bilearner.com | K32: CCDR | L32: Future Start | M32: Full-Time | N32: Zone A | O32: Temporary | P32: Resignation | Q32: Sales | R32: Catv | S32: 33179 | T32: TX | U32: Lineman | V32: Male | W32: 57302 | X32: Needs Improvement | Y32: 2 | Z32: 3482 | AA32: 22-10-2022 | AB32: 4 | AC32: 5 | AD32: 44988 | AE32: Technical Skills | AF32: Internal | AG32: Failed | AH32: Saraland | AI32: Jennifer Brown | AJ32: 1 | AK32: 627.11
